<?xml version="1.0" encoding="utf-8"?>
<!-- This URDF was automatically created by SolidWorks to URDF Exporter! Originally created by Stephen Brawner (brawner@gmail.com) 
     Commit Version: 1.6.0-4-g7f85cfe  Build Version: 1.6.7995.38578
     For more information, please see http://wiki.ros.org/sw_urdf_exporter -->
<robot
  name="little_car_urdf">
  <link
    name="base_link">
    <inertial>
      <origin
        xyz="-0.0214296564968354 0 0.0568815827004748"
        rpy="0 0 0" />
      <mass
        value="11.4693081230504" />
      <inertia
        ixx="0.102397555270709"
        ixy="-4.26772392736101E-18"
        ixz="0.00961016950477449"
        iyy="0.127224060887284"
        iyz="2.43267071072973E-18"
        izz="0.193556630818574" />
    </inertial>
    <visual>
      <origin
        xyz="0 0 0"
        rpy="0 0 0" />
      <geometry>
        <mesh
          filename="package://little_car_urdf/meshes/base_link.STL" />
      </geometry>
      <material
        name="">
        <color
          rgba="1 1 1 1" />
      </material>
    </visual>
    <collision>
      <origin
        xyz="0 0 0"
        rpy="0 0 0" />
      <geometry>
        <mesh
          filename="package://little_car_urdf/meshes/base_link.STL" />
      </geometry>
    </collision>
  </link>
  <link
    name="fl">
    <inertial>
      <origin
        xyz="0 -1.3878E-17 0.015"
        rpy="0 0 0" />
      <mass
        value="0.10603" />
      <inertia
        ixx="3.7725E-05"
        ixy="1.406E-41"
        ixz="-4.5918E-38"
        iyy="3.7725E-05"
        iyz="-4.3114E-38"
        izz="6.1135E-05" />
    </inertial>
    <visual>
      <origin
        xyz="0 0 0"
        rpy="0 0 0" />
      <geometry>
        <mesh
          filename="package://little_car_urdf/meshes/fl.STL" />
      </geometry>
      <material
        name="">
        <color
          rgba="1 1 1 1" />
      </material>
    </visual>
    <collision>
      <origin
        xyz="0 0 0"
        rpy="0 0 0" />
      <geometry>
        <mesh
          filename="package://little_car_urdf/meshes/fl.STL" />
      </geometry>
    </collision>
  </link>
  <joint
    name="fl"
    type="continuous">
    <origin
      xyz="0.13 0.165 0"
      rpy="-1.5708 0 3.1416" />
    <parent
      link="base_link" />
    <child
      link="fl" />
    <axis
      xyz="0 0 -1" />
    <limit
      lower="-6"
      upper="6"
      effort="6"
      velocity="6" />
  </joint>
  <link
    name="fr">
    <inertial>
      <origin
        xyz="0 -1.3878E-17 -0.015"
        rpy="0 0 0" />
      <mass
        value="0.10603" />
      <inertia
        ixx="3.7725E-05"
        ixy="1.406E-41"
        ixz="-4.5918E-38"
        iyy="3.7725E-05"
        iyz="-4.3114E-38"
        izz="6.1135E-05" />
    </inertial>
    <visual>
      <origin
        xyz="0 0 0"
        rpy="0 0 0" />
      <geometry>
        <mesh
          filename="package://little_car_urdf/meshes/fr.STL" />
      </geometry>
      <material
        name="">
        <color
          rgba="1 1 1 1" />
      </material>
    </visual>
    <collision>
      <origin
        xyz="0 0 0"
        rpy="0 0 0" />
      <geometry>
        <mesh
          filename="package://little_car_urdf/meshes/fr.STL" />
      </geometry>
    </collision>
  </link>
  <joint
    name="fr"
    type="continuous">
    <origin
      xyz="0.13 -0.165 0"
      rpy="-1.5708 0 3.1416" />
    <parent
      link="base_link" />
    <child
      link="fr" />
    <axis
      xyz="0 0 -1" />
    <limit
      lower="-6"
      upper="6"
      effort="6"
      velocity="6" />
  </joint>
  <link
    name="bl">
    <inertial>
      <origin
        xyz="-1.3878E-17 -1.3878E-17 0.015"
        rpy="0 0 0" />
      <mass
        value="0.10603" />
      <inertia
        ixx="3.7725E-05"
        ixy="1.406E-41"
        ixz="-4.5918E-38"
        iyy="3.7725E-05"
        iyz="-4.3114E-38"
        izz="6.1135E-05" />
    </inertial>
    <visual>
      <origin
        xyz="0 0 0"
        rpy="0 0 0" />
      <geometry>
        <mesh
          filename="package://little_car_urdf/meshes/bl.STL" />
      </geometry>
      <material
        name="">
        <color
          rgba="1 1 1 1" />
      </material>
    </visual>
    <collision>
      <origin
        xyz="0 0 0"
        rpy="0 0 0" />
      <geometry>
        <mesh
          filename="package://little_car_urdf/meshes/bl.STL" />
      </geometry>
    </collision>
  </link>
  <joint
    name="bl"
    type="continuous">
    <origin
      xyz="-0.13 0.165 0"
      rpy="-1.5708 0 3.1416" />
    <parent
      link="base_link" />
    <child
      link="bl" />
    <axis
      xyz="0 0 -1" />
    <limit
      lower="-6"
      upper="6"
      effort="6"
      velocity="6" />
  </joint>
  <link
    name="br">
    <inertial>
      <origin
        xyz="0 -1.3878E-17 -0.015"
        rpy="0 0 0" />
      <mass
        value="0.10603" />
      <inertia
        ixx="3.7725E-05"
        ixy="6.7309E-23"
        ixz="-1.9521E-22"
        iyy="3.7725E-05"
        iyz="-4.0863E-22"
        izz="6.1135E-05" />
    </inertial>
    <visual>
      <origin
        xyz="0 0 0"
        rpy="0 0 0" />
      <geometry>
        <mesh
          filename="package://little_car_urdf/meshes/br.STL" />
      </geometry>
      <material
        name="">
        <color
          rgba="1 1 1 1" />
      </material>
    </visual>
    <collision>
      <origin
        xyz="0 0 0"
        rpy="0 0 0" />
      <geometry>
        <mesh
          filename="package://little_car_urdf/meshes/br.STL" />
      </geometry>
    </collision>
  </link>
  <joint
    name="br"
    type="continuous">
    <origin
      xyz="-0.13 -0.165 0"
      rpy="-1.5708 0 3.1416" />
    <parent
      link="base_link" />
    <child
      link="br" />
    <axis
      xyz="0 0 -1" />
    <limit
      lower="-6"
      upper="6"
      effort="6"
      velocity="6" />
  </joint>

  <!--add lidar-->

  <link name="laser_link">
        <inertial>
            <mass value="0.1" />
            <origin xyz="0 0 0" />
            <inertia ixx="0.01" ixy="0.0" ixz="0.0"
                        iyy="0.01" iyz="0.0"
                        izz="0.01" />
        </inertial>

        <visual>
            <origin xyz=" 0 0 0 " rpy="0 0 0" />
            <geometry>
                <cylinder length="0.05" radius="0.05"/>
            </geometry>
            <material name="black"/>
        </visual>

        <collision>
            <origin xyz="0.0 0.0 0.0" rpy="0 0 0" />
            <geometry>
                <cylinder length="0.05" radius="0.05"/>
            </geometry>
        </collision>
    </link>

	<joint name="rplidar_joint" type="fixed">
		<origin xyz="-0.05 0 0.18" rpy="0 0 0" />
		<parent link="base_link"/>
		<child link="laser_link"/>
	</joint>

    <gazebo reference="laser_link">
        <material>Gazebo/Grey</material>
    </gazebo>

    <gazebo reference="laser_link">
        <sensor type="ray" name="rplidar">
            <pose>0 0 0 0 0 0</pose>
            <visualize>false</visualize>
            <update_rate>40</update_rate>
            <ray>
                <scan>
                    <horizontal>
                    <samples>360</samples>
                    <resolution>1</resolution>
                    <min_angle>-3.14</min_angle>
                    <max_angle>3.14</max_angle>
                    </horizontal>
                </scan>
                <range>
                    <min>0.10</min>
                    <max>30.0</max>
                    <resolution>0.01</resolution>
                </range>
                <noise>
                    <type>gaussian</type>
                    <mean>0.0</mean>
                    <stddev>0.01</stddev>
                </noise>
            </ray>
            <plugin name="gazebo_rplidar" filename="libgazebo_ros_laser.so">
                <topicName>/scan</topicName>
                <frameName>laser_link</frameName>
            </plugin>
        </sensor>
    </gazebo>

    <gazebo>
      <plugin name="little_car_drive_controller" filename="libgazebo_ros_planar_move.so">
          <commandTopic>cmd_vel</commandTopic>
          <odometryTopic>odom</odometryTopic>
          <odometryFrame>odom</odometryFrame>
          <odometryRate>50</odometryRate>
          <robotBaseFrame>base_link</robotBaseFrame>
      </plugin>
    </gazebo>

    <!--color-->
    <gazebo reference="base_link">
        <material>Gazebo/Red</material>
    </gazebo>

    <gazebo reference="fl">
        <material>Gazebo/Black</material>
    </gazebo>

    <gazebo reference="fr">
        <material>Gazebo/Black</material>
    </gazebo>

    <gazebo reference="bl">
        <material>Gazebo/Black</material>
    </gazebo>

    <gazebo reference="br">
        <material>Gazebo/Black</material>
    </gazebo>

</robot>